Workbook

Sheet Raw_Data
A1: user_id | B1: signup_date | C1: experiment_group | D1: region | E1: device_type | F1: traffic_source | G1: plan_type | H1: visited_landing_page | I1: started_trial | J1: completed_onboarding | K1: converted_to_paid | L1: revenue_30d | M1: support_tickets_30d | N1: refund_requested | O1: days_to_convert | P1: engagement_score
A2: USR-100001 | B2: 45732 | C2: Control | D2: North | E2: Desktop | F2: Email | G2: Basic | H2: 0 | I2: 0 | J2: 0 | K2: 0 | L2: 0 | M2: 0 | N2: 0 | P2: 45.7
A3: USR-100002 | B3: 45724 | C3: Control | D3: West | E3: Mobile | F3: Organic | G3: Free | H3: 1 | I3: 0 | J3: 0 | K3: 0 | L3: 0 | M3: 0 | N3: 0 | P3: 48.6
A4: USR-100003 | B4: 45771 | C4: Control | D4: East | E4: Mobile | F4: Paid Search | G4: Premium | H4: 1 | I4: 0 | J4: 0 | K4: 0 | L4: 0 | M4: 1 | N4: 0 | P4: 35.4
A5: USR-100004 | B5: 45781 | C5: Control | D5: South | E5: Mobile | F5: Email | G5: Basic | H5: 1 | I5: 0 | J5: 0 | K5: 0 | L5: 0 | M5: 0 | N5: 0 | P5: 64.6
A6: USR-100005 | B6: 45700 | C6: Control | D6: North | E6: Tablet | F6: Organic | G6: Free | H6: 0 | I6: 0 | J6: 0 | K6: 0 | L6: 0 | M6: 0 | N6: 0 | P6: 66.6
A7: USR-100006 | B7: 45685 | C7: Control | D7: East | E7: Mobile | F7: Organic | G7: Premium | H7: 1 | I7: 0 | J7: 0 | K7: 0 | L7: 0 | M7: 0 | N7: 0 | P7: 40.8
A8: USR-100007 | B8: 45755 | C8: Control | D8: East | E8: Mobile | F8: Paid Search | G8: Basic | H8: 1 | I8: 1 | J8: 0 | K8: 0 | L8: 0 | M8: 0 | N8: 0 | P8: 57.1
A9: USR-100008 | B9: 45794 | C9: Control | D9: South | E9: Mobile | F9: Paid Search | G9: Free | H9: 0 | I9: 0 | J9: 0 | K9: 0 | L9: 0 | M9: 0 | N9: 0 | P9: 36.4
A10: USR-100009 | B10: 45711 | C10: Control | D10: South | E10: Tablet | F10: Referral | G10: Basic | H10: 0 | I10: 0 | J10: 0 | K10: 0 | L10: 0 | M10: 0 | N10: 0 | P10: 55.4
A11: USR-100010 | B11: 45806 | C11: Control | D11: West | E11: Desktop | F11: Social | G11: Free | H11: 1 | I11: 0 | J11: 0 | K11: 0 | L11: 0 | M11: 0 | N11: 0 | P11: 57.3
A12: USR-100011 | B12: 45777 | C12: Control | D12: East | E12: Mobile | F12: Paid Search | G12: Basic | H12: 1 | I12: 1 | J12: 1 | K12: 0 | L12: 0 | M12: 0 | N12: 0 | P12: 63.6
A13: USR-100012 | B13: 45732 | C13: Control | D13: East | E13: Mobile | F13: Social | G13: Premium | H13: 1 | I13: 1 | J13: 1 | K13: 0 | L13: 0 | M13: 1 | N13: 0 | P13: 80.4
... A60: USR-100059 | B60: 45761 | C60: Control | D60: North | E60: Mobile | F60: Social | G60: Free | H60: 0 | I60: 0 | J60: 0 | K60: 0 | L60: 0 | M60: 2 | N60: 0 | P60: 48.9
A61: USR-100060 | B61: 45658 | C61: Control | D61: West | E61: Mobile | F61: Social | G61: Free | H61: 1 | I61: 1 | J61: 1 | K61: 1 | L61: 240.42 | M61: 0 | N61: 0 | O61: 16 | P61: 56.5
A62: USR-100061 | B62: 45749 | C62: Control | D62: South | E62: Mobile | F62: Referral | G62: Free | H62: 1 | I62: 0 | J62: 0 | K62: 0 | L62: 0 | M62: 0 | N62: 0 | P62: 53.7
A63: USR-100062 | B63: 45745 | C63: Control | D63: North | E63: Mobile | F63: Social | G63: Premium | H63: 0 | I63: 0 | J63: 0 | K63: 0 | L63: 0 | M63: 0 | N63: 0 | P63: 62.2
A64: USR-100063 | B64: 45792 | C64: Control | D64: South | E64: Desktop | F64: Organic | G64: Free | H64: 1 | I64: 0 | J64: 0 | K64: 0 | L64: 0 | M64: 0 | N64: 0 | P64: 50.2
A65: USR-100064 | B65: 45758 | C65: Control | D65: North | E65: Mobile | F65: Organic | G65: Basic | H65: 1 | I65: 0 | J65: 0 | K65: 0 | L65: 0 | M65: 0 | N65: 0 | P65: 74.3
A66: USR-100065 | B66: 45723 | C66: Control | D66: South | E66: Desktop | F66: Paid Search | G66: Free | H66: 1 | I66: 0 | J66: 0 | K66: 0 | L66: 0 | M66: 0 | N66: 0 | P66: 58
A67: USR-100066 | B67: 45807 | C67: Control | D67: South | E67: Mobile | F67: Organic | G67: Free | H67: 0 | I67: 0 | J67: 0 | K67: 0 | L67: 0 | M67: 0 | N67: 0 | P67: 46.7
A68: USR-100067 | B68: 45664 | C68: Control | D68: South | E68: Desktop | F68: Organic | G68: Premium | H68: 1 | I68: 0 | J68: 0 | K68: 0 | L68: 0 | M68: 1 | N68: 0 | P68: 49.6
A69: USR-100068 | B69: 45785 | C69: Control | D69: West | E69: Mobile | F69: Social | G69: Free | H69: 0 | I69: 0 | J69: 0 | K69: 0 | L69: 0 | M69: 0 | N69: 0 | P69: 60.4
A70: USR-100069 | B70: 45735 | C70: Control | D70: East | E70: Desktop | F70: Email | G70: Free | H70: 1 | I70: 1 | J70: 1 | K70: 0 | L70: 0 | M70: 0 | N70: 0 | P70: 55.3
A71: USR-100070 | B71: 45793 | C71: Control | D71: North | E71: Desktop | F71: Organic | G71: Free | H71: 0 | I71: 0 | J71: 0 | K71: 0 | L71: 0 | M71: 0 | N71: 0 | P71: 56.2
A72: USR-100071 | B72: 45724 | C72: Control | D72: West | E72: Mobile | F72: Email | G72: Free | H72: 0 | I72: 0 | J72: 0 | K72: 0 | L72: 0 | M72: 0 | N72: 0 | P72: 29.4
A73: USR-100072 | B73: 45724 | C73: Control | D73: East | E73: Mobile | F73: Email | G73: Free | H73: 1 | I73: 0 | J73: 0 | K73: 0 | L73: 0 | M73: 0 | N73: 0 | P73: 54.2
... A79: USR-100078 | B79: 45673 | C79: Control | D79: North | E79: Mobile | F79: Organic | G79: Free | H79: 0 | I79: 0 | J79: 0 | K79: 0 | L79: 0 | M79: 2 | N79: 0 | P79: 48.4
A80: USR-100079 | B80: 45708 | C80: Control | D80: West | E80: Desktop | F80: Organic | G80: Free | H80: 1 | I80: 1 | J80: 1 | K80: 1 | L80: 457.51 | M80: 0 | N80: 0 | O80: 7 | P80: 38
A81: USR-100080 | B81: 45798 | C81: Control | D81: East | E81: Mobile | F81: Social | G81: Free | H81: 1 | I81: 0 | J81: 0 | K81: 0 | L81: 0 | M81: 0 | N81: 0 | P81: 44.2
A82: USR-100081 | B82: 45785 | C82: Control | D82: South | E82: Mobile | F82: Organic | G82: Free | H82: 1 | I82: 1 | J82: 1 | K82: 0 | L82: 0 | M82: 0 | N82: 0 | P82: 81.2
A83: USR-100082 | B83: 45724 | C83: Control | D83: South | E83: Mobile | F83: Referral | G83: Free | H83: 1 | I83: 1 | J83: 0 | K83: 0 | L83: 0 | M83: 0 | N83: 0 | P83: 63.8
A84: USR-100083 | B84: 45748 | C84: Control | D84: South | E84: Desktop | F84: Email | G84: Free | H84: 0 | I84: 0 | J84: 0 | K84: 0 | L84: 0 | M84: 0 | N84: 0 | P84: 64.7
A85: USR-100084 | B85: 45719 | C85: Control | D85: West | E85: Mobile | F85: Social | G85: Basic | H85: 0 | I85: 0 | J85: 0 | K85: 0 | L85: 0 | M85: 0 | N85: 0 | P85: 60.4
A86: USR-100085 | B86: 45763 | C86: Control | D86: South | E86: Mobile | F86: Paid Search | G86: Free | H86: 0 | I86: 0 | J86: 0 | K86: 0 | L86: 0 | M86: 0 | N86: 0 | P86: 66.6
A87: USR-100086 | B87: 45666 | C87: Control | D87: North | E87: Desktop | F87: Organic | G87: Free | H87: 1 | I87: 0 | J87: 0 | K87: 0 | L87: 0 | M87: 0 | N87: 0 | P87: 50.9
A88: USR-100087 | B88: 45679 | C88: Control | D88: West | E88: Desktop | F88: Social | G88: Basic | H88: 0 | I88: 0 | J88: 0 | K88: 0 | L88: 0 | M88: 0 | N88: 0 | P88: 51
A89: USR-100088 | B89: 45777 | C89: Control | D89: South | E89: Mobile | F89: Email | G89: Premium | H89: 0 | I89: 0 | J89: 0 | K89: 0 | L89: 0 | M89: 0 | N89: 0 | P89: 65.8
A90: USR-100089 | B90: 45772 | C90: Control | D90: North | E90: Mobile | F90: Referral | G90: Basic | H90: 1 | I90: 0 | J90: 0 | K90: 0 | L90: 0 | M90: 0 | N90: 0 | P90: 61.8
A91: USR-100090 | B91: 45689 | C91: Control | D91: North | E91: Mobile | F91: Organic | G91: Basic | H91: 1 | I91: 0 | J91: 0 | K91: 0 | L91: 0 | M91: 0 | N91: 0 | P91: 54.5
...

Sheet Overall Summary
A1: Metric | B1: Control | C1: Treatment
A2: User Count | B2: =COUNTIF(Raw_Data!C:C,"Control") -> 693 | C2: =COUNTIF(Raw_Data!C:C,"Treatment") -> 715
A3: Landing Page Visit Rate | B3: =COUNTIFS(Raw_Data!C:C,"Control",Raw_Data!H:H,1)/COUNTIF(Raw_Data!C:C,"Control") -> 0.63636364 | C3: =COUNTIFS(Raw_Data!C:C,"Treatment",Raw_Data!H:H,1)/COUNTIF(Raw_Data!C:C,"Treatment") -> 0.72587413
A4: Trial Start Rate | B4: =COUNTIFS(Raw_Data!C:C,"Control",Raw_Data!I:I,1)/COUNTIF(Raw_Data!C:C,"Control") -> 0.25108225 | C4: =COUNTIFS(Raw_Data!C:C,"Treatment",Raw_Data!I:I,1)/COUNTIF(Raw_Data!C:C,"Treatment") -> 0.29090909
A5: Onboarding Completion Rate | B5: =COUNTIFS(Raw_Data!C:C,"Control",Raw_Data!J:J,1)/COUNTIF(Raw_Data!C:C,"Control") -> 0.15584416 | C5: =COUNTIFS(Raw_Data!C:C,"Treatment",Raw_Data!J:J,1)/COUNTIF(Raw_Data!C:C,"Treatment") -> 0.21258741
A6: Paid Conversion Rate | B6: =COUNTIFS(Raw_Data!C:C,"Control",Raw_Data!K:K,1)/COUNTIF(Raw_Data!C:C,"Control") -> 0.031746032 | C6: =COUNTIFS(Raw_Data!C:C,"Treatment",Raw_Data!K:K,1)/COUNTIF(Raw_Data!C:C,"Treatment") -> 0.06993007
A7: Average Revenue per User | B7: =SUMIFS(Raw_Data!L:L,Raw_Data!C:C,"Control")/COUNTIF(Raw_Data!C:C,"Control") -> 51.749322 | C7: =SUMIFS(Raw_Data!L:L,Raw_Data!C:C,"Treatment")/COUNTIF(Raw_Data!C:C,"Treatment") -> 53.875119
A8: Average Revenue per Converted User | B8: =SUMIFS(Raw_Data!L:L,Raw_Data!C:C,"Control",Raw_Data!K:K,1)/COUNTIFS(Raw_Data!C:C,"Control",Raw_Data!K:K,1) -> 1630.1036 | C8: =SUMIFS(Raw_Data!L:L,Raw_Data!C:C,"Treatment",Raw_Data!K:K,1)/COUNTIFS(Raw_Data!C:C,"Treatment",Raw_Data!K:K,1) -> 770.4142
A9: Refund Rate | B9: =COUNTIFS(Raw_Data!C:C,"Control",Raw_Data!N:N,1)/COUNTIF(Raw_Data!C:C,"Control") -> 0 | C9: =COUNTIFS(Raw_Data!C:C,"Treatment",Raw_Data!N:N,1)/COUNTIF(Raw_Data!C:C,"Treatment") -> 0.0041958042
A10: Support Ticket Rate | B10: =COUNTIFS(Raw_Data!C:C,"Control",Raw_Data!M:M,">0")/COUNTIF(Raw_Data!C:C,"Control") -> 0.14718615 | C10: =COUNTIFS(Raw_Data!C:C,"Treatment",Raw_Data!M:M,">0")/COUNTIF(Raw_Data!C:C,"Treatment") -> 0.24755245
A11: Average Engagement Score | B11: =AVERAGEIFS(Raw_Data!P:P,Raw_Data!C:C,"Control") -> 57.026201 | C11: =AVERAGEIFS(Raw_Data!P:P,Raw_Data!C:C,"Treatment") -> 62.931966
A12: Average Days to Convert | B12: =AVERAGEIFS(Raw_Data!O:O,Raw_Data!C:C,"Control",Raw_Data!K:K,1) -> 8.8636364 | C12: =AVERAGEIFS(Raw_Data!O:O,Raw_Data!C:C,"Treatment",Raw_Data!K:K,1) -> 6.4

Sheet Region Analysis_x0009_
B2: Column Labels
B3: Control | F3: Treatment | J3: Total Count of user_id | K3: Total Count of converted_to_paid | L3: Total Average of revenue_30d | M3: Total Average of engagement_score
A4: Region Analysis | B4: Count of user_id | C4: Count of converted_to_paid | D4: Average of revenue_30d | E4: Average of engagement_score | F4: Count of user_id | G4: Count of converted_to_paid | H4: Average of revenue_30d | I4: Average of engagement_score
A5: East | B5: 158 | C5: 0.47878788 | D5: 18.116076 | E5: 56.628481 | F5: 172 | G5: 0.52121212 | H5: 46.504651 | I5: 63.187719 | J5: 330 | K5: 1 | L5: 32.912545 | M5: 60.03769
A6: North | B6: 203 | C6: 0.53002611 | D6: 83.667586 | E6: 57.5445 | F6: 180 | G6: 0.46997389 | H6: 80.9675 | I6: 63.153977 | J6: 383 | K6: 1 | L6: 82.398616 | M6: 60.170213
A7: South | B7: 184 | C7: 0.5 | D7: 76.033098 | E7: 56.904972 | F7: 184 | G7: 0.5 | H7: 47.001685 | I7: 62.158242 | J7: 368 | K7: 1 | L7: 61.517391 | M7: 59.538843
A8: West | B8: 148 | C8: 0.45259939 | D8: 13.684662 | E8: 56.898649 | F8: 179 | G8: 0.54740061 | H8: 40.77905 | I8: 63.257865 | J8: 327 | K8: 1 | L8: 28.516147 | M8: 60.370859
A9: Grand Total | B9: 693 | C9: 0.4921875 | D9: 51.749322 | E9: 57.026201 | F9: 715 | G9: 0.5078125 | H9: 53.875119 | I9: 62.931966 | J9: 1408 | K9: 1 | L9: 52.828828 | M9: 60.021449
D11: Region Analysis

Sheet Device Analysis_x0009_
C5: Column Labels
C6: Control | G6: Treatment | K6: Total Count of user_id | L6: Total Average of revenue_30d | M6: Total Average of engagement_score | N6: Total Count of converted_to_paid
B7: Row Labels | C7: Count of user_id | D7: Average of revenue_30d | E7: Average of engagement_score | F7: Count of converted_to_paid | G7: Count of user_id | H7: Average of revenue_30d | I7: Average of engagement_score | J7: Count of converted_to_paid
B8: Desktop | C8: 200 | D8: 84.94295 | E8: 57.212563 | F8: 0.48309179 | G8: 214 | H8: 40.958131 | I8: 63.245283 | J8: 0.51690821 | K8: 414 | L8: 62.206836 | M8: 60.324331 | N8: 1
B9: Mobile | C9: 428 | D9: 41.847967 | E9: 57.347877 | F9: 0.49537037 | G9: 436 | H9: 58.828349 | I9: 62.783721 | J9: 0.50462963 | K9: 864 | L9: 50.416771 | M9: 60.084895 | N9: 1
B10: Tablet | C10: 56 | D10: 7.3105357 | E10: 55.758182 | F10: 0.5 | G10: 56 | H10: 73.330536 | I10: 63.007143 | J10: 0.5 | K10: 112 | L10: 40.320536 | M10: 59.415315 | N10: 1
B11: (blank) | C11: 9 | D11: 61.485556 | E11: 45.5 | F11: 0.5 | G11: 9 | H11: 0 | I11: 62.166667 | J11: 0.5 | K11: 18 | L11: 30.742778 | M11: 53.833333 | N11: 1
B12: Grand Total | C12: 693 | D12: 51.749322 | E12: 57.026201 | F12: 0.4921875 | G12: 715 | H12: 53.875119 | I12: 62.931966 | J12: 0.5078125 | K12: 1408 | L12: 52.828828 | M12: 60.021449 | N12: 1
H14: Device Analysis

Sheet Traffic Source Analysis_x0009_
C2: Column Labels
C3: Control | G3: Treatment | K3: Total Count of user_id | L3: Total Average of revenue_30d | M3: Total Average of engagement_score | N3: Total Count of converted_to_paid
B4: Row Labels | C4: Count of user_id | D4: Average of revenue_30d | E4: Average of engagement_score | F4: Count of converted_to_paid | G4: Count of user_id | H4: Average of revenue_30d | I4: Average of engagement_score | J4: Count of converted_to_paid
B5: Email | C5: 74 | D5: 28.720676 | E5: 57.828378 | F5: 0.56923077 | G5: 56 | H5: 44.980893 | I5: 62.241071 | J5: 0.43076923 | K5: 130 | L5: 35.725077 | M5: 59.729231 | N5: 1
B6: Organic | C6: 246 | D6: 42.512602 | E6: 58.451429 | F6: 0.50513347 | G6: 241 | H6: 50.70639 | I6: 61.54135 | J6: 0.49486653 | K6: 487 | L6: 46.567433 | M6: 59.970747 | N6: 1
B7: Paid Search | C7: 156 | D7: 10.837436 | E7: 54.565806 | F7: 0.46987952 | G7: 176 | H7: 34.781591 | I7: 62.82931 | J7: 0.53012048 | K7: 332 | L7: 23.530723 | M7: 58.93617 | N7: 1
B8: Referral | C8: 81 | D8: 33.310988 | E8: 58.3725 | F8: 0.47093023 | G8: 91 | H8: 103.00418 | I8: 64.202222 | J8: 0.52906977 | K8: 172 | L8: 70.183547 | M8: 61.458824 | N8: 1
B9: Social | C9: 130 | D9: 136.08715 | E9: 55.909449 | F9: 0.49429658 | G9: 133 | H9: 51.552105 | I9: 63.819697 | J9: 0.50570342 | K9: 263 | L9: 93.33749 | M9: 59.940927 | N9: 1
B10: (blank) | C10: 6 | D10: 199.78167 | E10: 58.183333 | F10: 0.25 | G10: 18 | H10: 79.453889 | I10: 71.522222 | J10: 0.75 | K10: 24 | L10: 109.53583 | M10: 68.1875 | N10: 1
B11: Grand Total | C11: 693 | D11: 51.749322 | E11: 57.026201 | F11: 0.4921875 | G11: 715 | H11: 53.875119 | I11: 62.931966 | J11: 0.5078125 | K11: 1408 | L11: 52.828828 | M11: 60.021449 | N11: 1
E13: Traffic source Analysis

Sheet Hypothesis_test
B1: Hypothesis Test
B3: Metric | C3: Values
B4: Control user | C4: 693
B5: Treatment User | C5: 715
B6: Control Success | C6: 22
B7: Treatment success | C7: 50
B8: Control proportion | C8: =C6/C4 -> 0.031746032
B9: Treatment proportion | C9: =C7/C5 -> 0.06993007
B10: Pooled proportion | C10: =(C6+C7)/(C4+C5) -> 0.051136364
B11: Standard error | C11: =SQRT(C10*(1-C10)*((1/C4)+(1/C5))) -> 0.011742174
B12: Z-score | C12: =(C9-C8)/C11 -> 3.2518713
B13: p- value (one tailed) | C13: =1-_xlfn.NORM.S.DIST(C12,TRUE) -> 0.00057323969
B14: Decision | C14: =IF(C13<0.05,"Reject H0","Fail to Reject H0") -> Reject H0
